[2025-07-13 16:35:32] Exception in process_command:
Traceback (most recent call last):
  File "/home/drx/DRX/drx_main.py", line 945, in process_command
    speak_wx_alerts(config, debug_log)
TypeError: speak_wx_alerts() takes 0 positional arguments but 2 were given

[2025-07-13 16:33:30] Exception in process_command:
Traceback (most recent call last):
  File "/home/drx/DRX/drx_main.py", line 945, in process_command
    speak_wx_alerts(config, debug_log)
TypeError: speak_wx_alerts() takes 0 positional arguments but 2 were given

[2025-07-13 16:33:24] Exception in process_command:
Traceback (most recent call last):
  File "/home/drx/DRX/drx_main.py", line 945, in process_command
    speak_wx_alerts(config, debug_log)
TypeError: speak_wx_alerts() takes 0 positional arguments but 2 were given

[2025-07-13 16:33:22] Exception in process_command:
Traceback (most recent call last):
  File "/home/drx/DRX/drx_main.py", line 945, in process_command
    speak_wx_alerts(config, debug_log)
TypeError: speak_wx_alerts() takes 0 positional arguments but 2 were given

[2025-07-13 16:32:35] Exception in process_command:
Traceback (most recent call last):
  File "/home/drx/DRX/drx_main.py", line 945, in process_command
    speak_wx_alerts(config, debug_log)
TypeError: speak_wx_alerts() takes 0 positional arguments but 2 were given

[2025-07-13 16:32:33] Exception in process_command:
Traceback (most recent call last):
  File "/home/drx/DRX/drx_main.py", line 945, in process_command
    speak_wx_alerts(config, debug_log)
TypeError: speak_wx_alerts() takes 0 positional arguments but 2 were given

[2025-07-13 16:26:58] Exception in process_command:
Traceback (most recent call last):
  File "/home/drx/DRX/drx_main.py", line 945, in process_command
    speak_wx_alerts(config, debug_log)
TypeError: speak_wx_alerts() takes 0 positional arguments but 2 were given

[2025-07-13 16:26:56] Exception in process_command:
Traceback (most recent call last):
  File "/home/drx/DRX/drx_main.py", line 945, in process_command
    speak_wx_alerts(config, debug_log)
TypeError: speak_wx_alerts() takes 0 positional arguments but 2 were given

[2025-07-13 16:26:53] Exception in process_command:
Traceback (most recent call last):
  File "/home/drx/DRX/drx_main.py", line 945, in process_command
    speak_wx_alerts(config, debug_log)
TypeError: speak_wx_alerts() takes 0 positional arguments but 2 were given

[2025-07-13 16:10:57] Exception in maybe_run_webcmd:
Traceback (most recent call last):
  File "/home/drx/DRX/drx_main.py", line 3069, in maybe_run_webcmd
    cmd = json.load(f)
          ^^^^^^^^^^^^
  File "/usr/lib/python3.11/json/__init__.py", line 293, in load
    return loads(fp.read(),
           ^^^^^^^^^^^^^^^^
  File "/usr/lib/python3.11/json/__init__.py", line 346, in loads
    return _default_decoder.decode(s)
           ^^^^^^^^^^^^^^^^^^^^^^^^^^
  File "/usr/lib/python3.11/json/decoder.py", line 337, in decode
    obj, end = self.raw_decode(s, idx=_w(s, 0).end())
               ^^^^^^^^^^^^^^^^^^^^^^^^^^^^^^^^^^^^^^
  File "/usr/lib/python3.11/json/decoder.py", line 355, in raw_decode
    raise JSONDecodeError("Expecting value", s, err.value) from None
json.decoder.JSONDecodeError: Expecting value: line 1 column 1 (char 0)

[2025-07-13 15:28:45] Exception in process_command:
Traceback (most recent call last):
  File "/home/drx/DRX/drx_main.py", line 945, in process_command
    speak_wx_alerts(config, debug_log)
TypeError: speak_wx_alerts() takes 0 positional arguments but 2 were given

[2025-07-13 15:17:26] Exception in process_command:
Traceback (most recent call last):
  File "/home/drx/DRX/drx_main.py", line 4166, in speak_wx_alerts
    keep_remote_active(True)
    ^^^^^^^^^^^^^^^^^^
NameError: name 'keep_remote_active' is not defined

During handling of the above exception, another exception occurred:

Traceback (most recent call last):
  File "/home/drx/DRX/drx_main.py", line 945, in process_command
    speak_wx_alerts(config, debug_log)
  File "/home/drx/DRX/drx_main.py", line 4189, in speak_wx_alerts
    keep_remote_active(False)  # Ensure remote is released on error
    ^^^^^^^^^^^^^^^^^^
NameError: name 'keep_remote_active' is not defined

[2025-07-13 15:14:27] Exception in process_command:
Traceback (most recent call last):
  File "/home/drx/DRX/drx_main.py", line 4166, in speak_wx_alerts
    keep_remote_active(True)
    ^^^^^^^^^^^^^^^^^^
NameError: name 'keep_remote_active' is not defined

During handling of the above exception, another exception occurred:

Traceback (most recent call last):
  File "/home/drx/DRX/drx_main.py", line 945, in process_command
    speak_wx_alerts(config, debug_log)
  File "/home/drx/DRX/drx_main.py", line 4189, in speak_wx_alerts
    keep_remote_active(False)  # Ensure remote is released on error
    ^^^^^^^^^^^^^^^^^^
NameError: name 'keep_remote_active' is not defined

